[2022-11-28T14:53:27Z] DEBUG    - Logging set up successfully
[2022-11-28T14:53:27Z] DEBUG    - Running generate: Namespace(version=False, subparser_name='generate', command=<function generate at 0x116aa04c0>, verbose=0, endpoint_url=None, region=None, target_schemas=[])
[2022-11-28T14:53:27Z] DEBUG    - Root directory: /Users/martin/repos/cloudsoft/cloudformation-fastly-resource-providers
[2022-11-28T14:53:27Z] DEBUG    - Loading project file '/Users/martin/repos/cloudsoft/cloudformation-fastly-resource-providers/.rpdk-config'
[2022-11-28T14:53:27Z] DEBUG    - Project file /Users/martin/repos/cloudsoft/cloudformation-fastly-resource-providers/.rpdk-config not found. Have you run 'init' or in a wrong directory?
Traceback (most recent call last):
  File "/Users/martin/.pyenv/versions/3.10.4/lib/python3.10/site-packages/rpdk/core/project.py", line 562, in load
    self.load_settings()
  File "/Users/martin/.pyenv/versions/3.10.4/lib/python3.10/site-packages/rpdk/core/project.py", line 234, in load_settings
    with self.settings_path.open("r", encoding="utf-8") as f:
  File "/Users/martin/.pyenv/versions/3.10.4/lib/python3.10/pathlib.py", line 1117, in open
    return self._accessor.open(self, mode, buffering, encoding, errors,
FileNotFoundError: [Errno 2] No such file or directory: '/Users/martin/repos/cloudsoft/cloudformation-fastly-resource-providers/.rpdk-config'
[2022-11-28T14:53:27Z] DEBUG    - Caught exit recommendation
Traceback (most recent call last):
  File "/Users/martin/.pyenv/versions/3.10.4/lib/python3.10/site-packages/rpdk/core/project.py", line 562, in load
    self.load_settings()
  File "/Users/martin/.pyenv/versions/3.10.4/lib/python3.10/site-packages/rpdk/core/project.py", line 234, in load_settings
    with self.settings_path.open("r", encoding="utf-8") as f:
  File "/Users/martin/.pyenv/versions/3.10.4/lib/python3.10/pathlib.py", line 1117, in open
    return self._accessor.open(self, mode, buffering, encoding, errors,
FileNotFoundError: [Errno 2] No such file or directory: '/Users/martin/repos/cloudsoft/cloudformation-fastly-resource-providers/.rpdk-config'

The above exception was the direct cause of the following exception:

Traceback (most recent call last):
  File "/Users/martin/.pyenv/versions/3.10.4/lib/python3.10/site-packages/rpdk/core/cli.py", line 100, in main
    args.command(args)
  File "/Users/martin/.pyenv/versions/3.10.4/lib/python3.10/site-packages/rpdk/core/generate.py", line 14, in generate
    project.load()
  File "/Users/martin/.pyenv/versions/3.10.4/lib/python3.10/site-packages/rpdk/core/project.py", line 564, in load
    self._raise_invalid_project(
  File "/Users/martin/.pyenv/versions/3.10.4/lib/python3.10/site-packages/rpdk/core/project.py", line 229, in _raise_invalid_project
    raise InvalidProjectError(msg) from e
rpdk.core.exceptions.InvalidProjectError: Project file /Users/martin/repos/cloudsoft/cloudformation-fastly-resource-providers/.rpdk-config not found. Have you run 'init' or in a wrong directory?
[2022-11-28T14:53:27Z] CRITICAL - Project file /Users/martin/repos/cloudsoft/cloudformation-fastly-resource-providers/.rpdk-config not found. Have you run 'init' or in a wrong directory?
